<mujoco model="turtlebot3_burger">
  <compiler angle="radian" meshdir="assets" autolimits="true"/>

  <option integrator="implicitfast"/>

  <asset>
    <mesh name="burger_base" file="burger_base.stl" scale="0.001 0.001 0.001"/>
    <mesh name="left_tire" file="left_tire.stl" scale="0.001 0.001 0.001"/>
    <mesh name="right_tire" file="right_tire.stl" scale="0.001 0.001 0.001"/>
    <mesh name="lds" file="lds.stl" scale="0.001 0.001 0.001"/>
  </asset>

  <worldbody>
    <geom pos="-0.032 0 0.01" type="mesh" rgba="0.4 0.4 0.4 1" mesh="burger_base"/>
    <geom size="0.015 0.0045 0.01" pos="-0.081 7.96327e-07 0.005" quat="0.707388 -0.706825 0 0" type="box"/>
    <geom pos="-0.032 0 0.182" quat="1 0 0 0" type="mesh" rgba="0.3 0.3 0.3 1" mesh="lds"/>
    <body name="wheel_left_link" pos="0 0.08 0.033" quat="0.707388 -0.706825 0 0">
      <inertial pos="0 0 0" quat="-0.000890159 0.706886 0.000889646 0.707326" mass="0.0284989" diaginertia="2.07126e-05 1.11924e-05 1.11756e-05"/>
      <joint name="wheel_left_joint" pos="0 0 0" axis="0 0 1"/>
      <geom quat="0.707388 0.706825 0 0" type="mesh" rgba="0.3 0.3 0.3 1" mesh="left_tire"/>
    </body>
    <body name="wheel_right_link" pos="0 -0.08 0.033" quat="0.707388 -0.706825 0 0">
      <inertial pos="0 0 0" quat="-0.000890159 0.706886 0.000889646 0.707326" mass="0.0284989" diaginertia="2.07126e-05 1.11924e-05 1.11756e-05"/>
      <joint name="wheel_right_joint" pos="0 0 0" axis="0 0 1"/>
      <geom quat="0.707388 0.706825 0 0" type="mesh" rgba="0.3 0.3 0.3 1" mesh="right_tire"/>
    </body>
  </worldbody>
</mujoco>
