<mujoco model="ffw">
  <compiler angle="radian" meshdir="assets" autolimits="true"/>

  <option integrator="implicitfast"/>

  <!--
    Default classes:
    1) "robot" for main body joints
    2) "hand" for the finger (gripper) joints
    3) "slider" specifically for the linear slide joint
  -->
  <default>
    <!-- Robot default -->
    <default class="robot">
      <!-- Increase armature or damping if you want more stability -->
      <joint range="-3.14 3.14" armature="0.5" damping="100.0" />
      <position kp="3000" forcerange="-1000 1000" ctrlrange="-3.14 3.14"/>
    </default>

    <!-- Hand (finger) default -->
    <default class="hand">
      <joint range="-1.57 1.57" armature="0.1" damping="10.0" frictionloss="1.0"/>
      <position kp="500" forcerange="-100 100" ctrlrange="-1.57 1.57"/>
    </default>

    <!-- Slider default (for the linear_joint) -->
    <default class="slider">
      <!--
        You can tune armature/damping further for the slide if necessary.
        'range' below sets the permissible linear travel.
      -->
      <joint type="slide" range="0 0.25" armature="10.0" damping="1000.0" frictionloss="100.0" />
      <position kp="10000" forcerange="-50000 50000" ctrlrange="0 0.25"/>
    </default>
  </default>

  <!-- Assets -->
  <asset>
    <mesh name="base_mobile_assy" file="ffw/base_mobile_assy.stl" scale="0.001 0.001 0.001"/>
    <mesh name="body_arm_assy" file="ffw/body_arm_assy.stl" scale="0.001 0.001 0.001"/>
    <mesh name="neck_link1" file="ffw/neck_link1.stl" scale="0.001 0.001 0.001"/>
    <mesh name="neck_link2" file="ffw/neck_link2.stl" scale="0.001 0.001 0.001"/>
    <mesh name="arm_r_link1" file="ffw/arm_r_link1.stl" scale="0.001 0.001 0.001"/>
    <mesh name="arm_r_link2" file="ffw/arm_r_link2.stl" scale="0.001 0.001 0.001"/>
    <mesh name="arm_r_link3" file="ffw/arm_r_link3.stl" scale="0.001 0.001 0.001"/>
    <mesh name="arm_r_link4" file="ffw/arm_r_link4.stl" scale="0.001 0.001 0.001"/>
    <mesh name="arm_r_link5" file="ffw/arm_r_link5.stl" scale="0.001 0.001 0.001"/>
    <mesh name="arm_r_link6" file="ffw/arm_r_link6.stl" scale="0.001 0.001 0.001"/>
    <mesh name="arm_r_link7" file="ffw/arm_r_link7.stl" scale="0.001 0.001 0.001"/>
    <mesh name="arm_l_link1" file="ffw/arm_l_link1.stl" scale="0.001 0.001 0.001"/>
    <mesh name="arm_l_link2" file="ffw/arm_l_link2.stl" scale="0.001 0.001 0.001"/>
    <mesh name="arm_l_link3" file="ffw/arm_l_link3.stl" scale="0.001 0.001 0.001"/>
    <mesh name="arm_l_link4" file="ffw/arm_l_link4.stl" scale="0.001 0.001 0.001"/>
    <mesh name="arm_l_link5" file="ffw/arm_l_link5.stl" scale="0.001 0.001 0.001"/>
    <mesh name="arm_l_link6" file="ffw/arm_l_link6.stl" scale="0.001 0.001 0.001"/>
    <mesh name="arm_l_link7" file="ffw/arm_l_link7.stl" scale="0.001 0.001 0.001"/>
    <mesh name="left_base_link" file="rf56dftp_left/left_base_link.STL"/>
    <mesh name="left_thumb_1" file="rf56dftp_left/left_thumb_1.STL"/>
    <mesh name="left_thumb_2" file="rf56dftp_left/left_thumb_2.STL"/>
    <mesh name="left_thumb_3" file="rf56dftp_left/left_thumb_3.STL"/>
    <mesh name="left_thumb_4" file="rf56dftp_left/left_thumb_4.STL"/>
    <mesh name="left_index_1" file="rf56dftp_left/left_index_1.STL"/>
    <mesh name="left_index_2" file="rf56dftp_left/left_index_2.STL"/>
    <mesh name="left_middle_1" file="rf56dftp_left/left_middle_1.STL"/>
    <mesh name="left_middle_2" file="rf56dftp_left/left_middle_2.STL"/>
    <mesh name="left_ring_1" file="rf56dftp_left/left_ring_1.STL"/>
    <mesh name="left_ring_2" file="rf56dftp_left/left_ring_2.STL"/>
    <mesh name="left_little_1" file="rf56dftp_left/left_little_1.STL"/>
    <mesh name="left_little_2" file="rf56dftp_left/left_little_2.STL"/>
    <mesh name="right_base_link" file="rf56dftp_right/right_base_link.STL"/>
    <mesh name="right_thumb_1" file="rf56dftp_right/right_thumb_1.STL"/>
    <mesh name="right_thumb_2" file="rf56dftp_right/right_thumb_2.STL"/>
    <mesh name="right_thumb_3" file="rf56dftp_right/right_thumb_3.STL"/>
    <mesh name="right_thumb_4" file="rf56dftp_right/right_thumb_4.STL"/>
    <mesh name="right_index_1" file="rf56dftp_right/right_index_1.STL"/>
    <mesh name="right_index_2" file="rf56dftp_right/right_index_2.STL"/>
    <mesh name="right_middle_1" file="rf56dftp_right/right_middle_1.STL"/>
    <mesh name="right_middle_2" file="rf56dftp_right/right_middle_2.STL"/>
    <mesh name="right_ring_1" file="rf56dftp_right/right_ring_1.STL"/>
    <mesh name="right_ring_2" file="rf56dftp_right/right_ring_2.STL"/>
    <mesh name="right_little_1" file="rf56dftp_right/right_little_1.STL"/>
    <mesh name="right_little_2" file="rf56dftp_right/right_little_2.STL"/>
  </asset>

  <worldbody>
    <geom type="mesh" rgba="0.75 0.75 0.75 1" mesh="base_mobile_assy"/>

    <!-- base_link with separate "slider" default class -->
    <body name="base_link" pos="0.053 0 1.2846">
      <inertial pos="-0.0460732 -2.28101e-05 -0.0270208" quat="0.295276 0.295528 -0.642514 0.642379" mass="8.72176" diaginertia="0.106112 0.0836519 0.0576143"/>
      <!-- Joint with slider class -->
      <joint name="linear_joint" class="slider" pos="0 0 0" axis="0 0 1" type="slide"/>
      <geom type="mesh" rgba="1 1 1 1" mesh="body_arm_assy"/>

      <!-- Neck -->
      <body name="neck_link1" pos="0.019 0 0.06475">
        <inertial pos="-0.00732988 0 0.0434363" quat="0.688381 -0.161651 -0.161651 0.688381" mass="0.139473" diaginertia="6.54445e-05 5.99779e-05 4.75755e-05"/>
        <joint name="neck_joint1" class="robot" pos="0 0 0" axis="0 1 0" range="0 0.4"/>
        <geom type="mesh" rgba="0.2 0.2 0.2 1" mesh="neck_link1"/>

        <body name="neck_link2" pos="0 0 0.0475">
          <inertial pos="0.00877907 -8.40392e-05 0.0425432" quat="0.653422 0.653616 0.269949 -0.270098" mass="0.145078" diaginertia="0.000186994 0.000179978 2.28387e-05"/>
          <joint name="neck_joint2" class="robot" pos="0 0 0" axis="0 0 1" range="-0.6 0.6"/>
          <geom type="mesh" rgba="1 1 1 1" mesh="neck_link2"/>
        </body>
      </body>

      <!-- Right arm -->
      <body name="arm_r_link1" pos="0 -0.1025 0">
        <inertial pos="0.0162454 -0.115083 -0.000116015" quat="0.212043 0.665609 -0.229062 0.677889" mass="1.93395" diaginertia="0.00305635 0.00275332 0.00221466"/>
        <joint name="arm_r_joint1" class="robot" pos="0 0 0" axis="0 1 0" range="-3.14 3.14"/>
        <geom type="mesh" rgba="0.2 0.2 0.2 1" mesh="arm_r_link1"/>

        <body name="arm_r_link2" pos="0 -0.123 0">
          <inertial pos="0.00904096 0.000105802 -0.144033" quat="0.707129 0.105833 0.108702 0.690617" mass="2.12414" diaginertia="0.0108559 0.0106863 0.00242145"/>
          <joint name="arm_r_joint2" class="robot" pos="0 0 0" axis="-1 0 0" range="0 3.14"/>
          <geom type="mesh" rgba="0.2 0.2 0.2 1" mesh="arm_r_link2"/>

          <body name="arm_r_link3" pos="0 0 -0.165">
            <inertial pos="-2.51092e-05 -0.0179472 -0.108765" quat="0.447823 0.894113 0.00400928 -0.000680335" mass="1.40774" diaginertia="0.00193273 0.0017314 0.00128994"/>
            <joint name="arm_r_joint3" class="robot" pos="0 0 0" axis="0 0 -1" range="-1.57 1.57"/>
            <geom type="mesh" rgba="0.2 0.2 0.2 1" mesh="arm_r_link3"/>

            <body name="arm_r_link4" pos="0 0 -0.117">
              <inertial pos="4.39703e-05 -0.00978736 -0.137888" quat="0.984402 0.175809 0.00125565 -0.00649329" mass="1.51314" diaginertia="0.00636295 0.00628021 0.00133398"/>
              <joint name="arm_r_joint4" class="robot" pos="0 0 0" axis="0 1 0" range="-1.86 1.86"/>
              <geom type="mesh" rgba="0.2 0.2 0.2 1" mesh="arm_r_link4"/>

              <body name="arm_r_link5" pos="0 0 -0.1559">
                <inertial pos="-2.62962e-05 -0.0187957 -0.0983871" quat="0.546043 0.837751 0.00318354 -0.000761107" mass="1.34419" diaginertia="0.00169762 0.00156986 0.00116911"/>
                <joint name="arm_r_joint5" class="robot" pos="0 0 0" axis="0 0 -1" range="-1.57 1.57"/>
                <geom type="mesh" rgba="0.2 0.2 0.2 1" mesh="arm_r_link5"/>

                <body name="arm_r_link6" pos="0 0 -0.1041">
                  <inertial pos="0.000339839 -0.0194304 -0.0639459" quat="0.662489 0.249825 -0.2542 0.658846" mass="0.636234" diaginertia="0.00155564 0.00138901 0.000496769"/>
                  <joint name="arm_r_joint6" class="robot" pos="0 0 0" axis="0 1 0" range="-1.57 1.57"/>
                  <geom type="mesh" rgba="0.2 0.2 0.2 1" mesh="arm_r_link6"/>

                  <body name="arm_r_link7" pos="0 0 -0.0885">
                    <inertial pos="-0.00242011 -0.00201564 -0.0911446" quat="0.703942 -0.0528198 -0.0236914 0.707894" mass="0.384359" diaginertia="0.00125471 0.0011001 0.000310982"/>
                    <joint name="arm_r_joint7" class="robot" pos="0 0 0" axis="-1 0 0" range="-1.046 1.046"/>
                    <geom type="mesh" rgba="0.2 0.2 0.2 1" mesh="arm_r_link7"/>

                    <!-- Right hand base -->
                    <geom pos="0 0 -0.05" quat="1 0 0 0" type="mesh" rgba="0.9 0.9 0.9 1" mesh="right_base_link"/>

                    <!-- Right thumb -->
                    <body name="right_thumb_1" pos="0.0269 0.02101 -0.119" quat="1.34924e-11 3.67321e-06 1 3.67321e-06">
                      <inertial pos="-0.00178423 0.000649411 0.00488589" quat="0.609481 0.695344 0.128437 -0.358515" mass="0.00115519" diaginertia="6.58579e-08 5.87769e-08 3.77927e-08"/>
                      <joint name="right_thumb_1_joint" class="hand" pos="0 0 0" axis="0 0 -1" range="0 1.15"/>
                      <geom type="mesh" rgba="0.9 0.9 0.9 1" mesh="right_thumb_1"/>

                      <body name="right_thumb_2" pos="-0.0063016 0.011924 0.003" quat="0.122797 0.122797 0.696364 0.696361">
                        <inertial pos="0.0141071 0.013272 -0.0090503" quat="0.653094 0.270971 -0.653141 0.271017" mass="0.016" diaginertia="1.39688e-06 1.14175e-06 9.89349e-07"/>
                        <joint name="right_thumb_2_joint" class="hand" pos="0 0 0" axis="0 0 1" range="0 0.55"/>
                        <geom type="mesh" rgba="0.9 0.9 0.9 1" mesh="right_thumb_2"/>

                        <body name="right_thumb_3" pos="0.034968 0.021325 -0.0015">
                          <inertial pos="0.00937844 0.00404408 -0.00753947" quat="0.686654 0.690582 -0.161401 -0.159853" mass="0.012" diaginertia="4.9004e-07 4.24794e-07 3.76617e-07"/>
                          <joint name="right_thumb_3_joint" class="hand" pos="0 0 0" axis="0 0 1" range="0 3.14"/>
                          <geom type="mesh" rgba="0.9 0.9 0.9 1" mesh="right_thumb_3"/>

                          <body name="right_thumb_4" pos="0.018887 0.011501 -0.0002">
                            <inertial pos="0.0109974 0.00131063 -0.00734352" quat="0.306916 0.308192 0.637344 0.636092" mass="0.01" diaginertia="9.67919e-07 9.25691e-07 4.39361e-07"/>
                            <joint name="right_thumb_4_joint" class="hand" pos="0 0 0" axis="0 0 1" range="0 3.14"/>
                            <geom type="mesh" rgba="0.9 0.9 0.9 1" mesh="right_thumb_4"/>
                          </body>
                        </body>
                      </body>
                    </body>

                    <!-- Right index -->
                    <body name="right_index_1" pos="0.038679 0.00056467 -0.2064" quat="0.508647 -0.491199 0.491201 -0.508648">
                      <inertial pos="-0.00183546 0.0123553 -0.00664922" quat="0.484907 0.514648 -0.484865 0.514692" mass="0.00719999" diaginertia="1.32925e-06 1.28623e-06 5.76964e-07"/>
                      <joint name="right_index_1_joint" class="hand" pos="0 0 0" axis="0 0 1" range="0 1.6"/>
                      <geom type="mesh" rgba="0.9 0.9 0.9 1" mesh="right_index_1"/>

                      <body name="right_index_2" pos="-0.0016312 0.032734 -0.00055">
                        <inertial pos="0.000405081 0.0257028 -0.00609276" quat="0.703612 0.702971 0.0715956 0.0750715" mass="0.00968594" diaginertia="2.34184e-06 2.30201e-06 3.04584e-07"/>
                        <joint name="right_index_2_joint" class="hand" pos="0 0 0" axis="0 0 1" range="0 3.14"/>
                        <geom type="mesh" rgba="0.9 0.9 0.9 1" mesh="right_index_2"/>
                      </body>
                    </body>

                    <!-- Right middle -->
                    <body name="right_middle_1" pos="0.0171 0.00056467 -0.207" quat="0.499998 -0.5 0.500002 -0.5">
                      <inertial pos="-0.00229221 0.0122787 -0.00664924" quat="0.47528 0.52355 -0.47524 0.523594" mass="0.00719999" diaginertia="1.32924e-06 1.28622e-06 5.76964e-07"/>
                      <joint name="right_middle_1_joint" class="hand" pos="0 0 0" axis="0 0 1" range="0 1.6"/>
                      <geom type="mesh" rgba="0.9 0.9 0.9 1" mesh="right_middle_1"/>

                      <body name="right_middle_2" pos="-0.0028436 0.032651 -0.00055">
                        <inertial pos="7.55635e-05 0.0274472 -0.00610051" quat="0.703921 0.703917 0.0669721 0.067155" mass="0.0104603" diaginertia="2.8477e-06 2.80695e-06 3.32744e-07"/>
                        <joint name="right_middle_2_joint" class="hand" pos="0 0 0" axis="0 0 1" range="0 3.14"/>
                        <geom type="mesh" rgba="0.9 0.9 0.9 1" mesh="right_middle_2"/>
                      </body>
                    </body>

                    <!-- Right ring -->
                    <body name="right_ring_1" pos="-0.0045302 0.00056467 -0.20683" quat="0.486728 -0.512927 0.512929 -0.48673">
                      <inertial pos="-0.00240481 0.0122572 -0.00664924" quat="0.472873 0.525725 -0.472833 0.52577" mass="0.00719999" diaginertia="1.32924e-06 1.28622e-06 5.76964e-07"/>
                      <joint name="right_ring_1_joint" class="hand" pos="0 0 0" axis="0 0 1" range="0 1.6"/>
                      <geom type="mesh" rgba="0.9 0.9 0.9 1" mesh="right_ring_1"/>

                      <body name="right_ring_2" pos="-0.0031431 0.032624 -0.00055">
                        <inertial pos="0.000666831 0.0256973 -0.00609276" quat="0.703985 0.703327 0.0680113 0.0714909" mass="0.00968594" diaginertia="2.34184e-06 2.30201e-06 3.04584e-07"/>
                        <joint name="right_ring_2_joint" class="hand" pos="0 0 0" axis="0 0 1" range="0 3.14"/>
                        <geom type="mesh" rgba="0.9 0.9 0.9 1" mesh="right_ring_2"/>
                      </body>
                    </body>

                    <!-- Right little -->
                    <body name="right_little_1" pos="-0.025916 0.00056467 -0.20365" quat="0.47315 -0.525478 0.52548 -0.473152">
                      <inertial pos="-0.00316845 0.0120824 -0.00664923" quat="0.456153 0.540294 -0.456113 0.54034" mass="0.00719995" diaginertia="1.32923e-06 1.28621e-06 5.76963e-07"/>
                      <joint name="right_little_1_joint" class="hand" pos="0 0 0" axis="0 0 1" range="0 1.6"/>
                      <geom type="mesh" rgba="0.9 0.9 0.9 1" mesh="right_little_1"/>

                      <body name="right_little_2" pos="-0.005182 0.032363 -0.00055" quat="0.707105 0 0 0.707108">
                        <inertial pos="0.0204417 -0.00469494 -0.0061" quat="0.482475 0.482374 0.517036 0.51692" mass="0.00759282" diaginertia="1.28167e-06 1.2391e-06 2.26514e-07"/>
                        <joint name="right_little_2_joint" class="hand" pos="0 0 0" axis="0 0 1" range="0 3.14"/>
                        <geom type="mesh" rgba="0.9 0.9 0.9 1" mesh="right_little_2"/>
                      </body>
                    </body>

                  </body>
                </body>
              </body>
            </body>
          </body>
        </body>
      </body>

      <!-- Left arm -->
      <body name="arm_l_link1" pos="0 0.1025 0">
        <inertial pos="0.0162539 0.115097 0.000116015" quat="-0.229615 0.677745 0.212586 0.665391" mass="1.93395" diaginertia="0.00305502 0.0027509 0.00221577"/>
        <joint name="arm_l_joint1" class="robot" pos="0 0 0" axis="0 1 0" range="-3.14 3.14"/>
        <geom type="mesh" rgba="0.2 0.2 0.2 1" mesh="arm_l_link1"/>

        <body name="arm_l_link2" pos="0 0.123 0">
          <inertial pos="0.00909681 -0.000105504 -0.144033" quat="0.692968 0.108459 0.106285 0.704795" mass="2.12414" diaginertia="0.0108537 0.0106882 0.00241736"/>
          <joint name="arm_l_joint2" class="robot" pos="0 0 0" axis="1 0 0" range="0 3.14"/>
          <geom type="mesh" rgba="0.2 0.2 0.2 1" mesh="arm_l_link2"/>

          <body name="arm_l_link3" pos="0 0 -0.165">
            <inertial pos="2.51092e-05 0.0179472 -0.108757" quat="0.894344 0.447371 -0.000598238 0.00281074" mass="1.40774" diaginertia="0.00193356 0.00173187 0.00129028"/>
            <joint name="arm_l_joint3" class="robot" pos="0 0 0" axis="0 0 1" range="-6.28 6.28"/>
            <geom type="mesh" rgba="0.2 0.2 0.2 1" mesh="arm_l_link3"/>

            <body name="arm_l_link4" pos="0 0 -0.117">
              <inertial pos="-4.39703e-05 0.00978704 -0.137888" quat="0.984403 -0.175803 -0.00125587 -0.00649472" mass="1.51314" diaginertia="0.00636289 0.00628017 0.00133396"/>
              <joint name="arm_l_joint4" class="robot" pos="0 0 0" axis="0 1 0" range="-1.86 1.86"/>
              <geom type="mesh" rgba="0.2 0.2 0.2 1" mesh="arm_l_link4"/>

              <body name="arm_l_link5" pos="0 0 -0.1559">
                <inertial pos="-4.95306e-05 0.0187957 -0.0983639" quat="0.838675 0.544584 0.00138926 -0.00713051" mass="1.34419" diaginertia="0.00169917 0.00156903 0.00116769"/>
                <joint name="arm_l_joint5" class="robot" pos="0 0 0" axis="0 0 1" range="-1.57 1.57"/>
                <geom type="mesh" rgba="0.2 0.2 0.2 1" mesh="arm_l_link5"/>

                <body name="arm_l_link6" pos="0 0 -0.1041">
                  <inertial pos="0.00038449 0.0194298 -0.0639456" quat="0.658925 -0.254422 0.24959 0.662414" mass="0.636234" diaginertia="0.00155561 0.00138897 0.00049676"/>
                  <joint name="arm_l_joint6" class="robot" pos="0 0 0" axis="0 1 0" range="-1.57 1.57"/>
                  <geom type="mesh" rgba="0.2 0.2 0.2 1" mesh="arm_l_link6"/>

                  <body name="arm_l_link7" pos="0 0 -0.0885">
                    <inertial pos="-0.00237181 0.00249345 -0.0980007" quat="0.707876 -0.0176581 -0.0477307 0.704501" mass="0.384359" diaginertia="0.00141022 0.00125626 0.000287964"/>
                    <joint name="arm_l_joint7" class="robot" pos="0 0 0" axis="1 0 0" range="-1.046 1.046"/>
                    <geom type="mesh" rgba="0.2 0.2 0.2 1" mesh="arm_l_link7"/>

                    <!-- Left hand base -->
                    <geom pos="0 0 -0.05" quat="1 0 0 0" type="mesh" rgba="0.9 0.9 0.9 1" mesh="left_base_link"/>

                    <!-- Left thumb -->
                    <body name="left_thumb_1" pos="0.0269 -0.02101 -0.12075">
                      <inertial pos="0.00178423 -0.000649405 -0.00313589" quat="0.609482 0.695344 0.128439 -0.358513" mass="0.00115519" diaginertia="6.58579e-08 5.87769e-08 3.77927e-08"/>
                      <joint name="left_thumb_1_joint" class="hand" pos="0 0 0" axis="0 0 -1" range="0 1.15"/>
                      <geom type="mesh" rgba="0.9 0.9 0.9 1" mesh="left_thumb_1"/>

                      <body name="left_thumb_2" pos="0.0063016 -0.011924 -0.00125" quat="0.696363 -0.696365 0.122789 -0.122789">
                        <inertial pos="0.0141077 0.0132729 0.00905028" quat="0.65319 0.270895 -0.653128 0.270891" mass="0.016" diaginertia="1.3971e-06 1.14195e-06 9.89493e-07"/>
                        <joint name="left_thumb_2_joint" class="hand" pos="0 0 0" axis="0 0 1" range="0 0.55"/>
                        <geom type="mesh" rgba="0.9 0.9 0.9 1" mesh="left_thumb_2"/>

                        <body name="left_thumb_3" pos="0.026828 0.02583 0.00315">
                          <inertial pos="0.0175211 -0.000458783 0.00589187" quat="0.689932 0.68741 -0.159656 -0.161158" mass="0.012" diaginertia="4.90101e-07 4.24725e-07 3.7664e-07"/>
                          <joint name="left_thumb_3_joint" class="hand" pos="0 0 0" axis="0 0 1" range="0 3.14"/>
                          <geom type="mesh" rgba="0.9 0.9 0.9 1" mesh="left_thumb_3"/>

                          <body name="left_thumb_4" pos="0.027027 0.0069965 -0.00145">
                            <inertial pos="0.0159973 0.00631058 0.00734331" quat="0.308125 0.306985 0.636085 0.63735" mass="0.01" diaginertia="9.67936e-07 9.25704e-07 4.39366e-07"/>
                            <joint name="left_thumb_4_joint" class="hand" pos="0 0 0" axis="0 0 1" range="0 3.14"/>
                            <geom type="mesh" rgba="0.9 0.9 0.9 1" mesh="left_thumb_4"/>
                          </body>
                        </body>
                      </body>
                    </body>

                    <!-- Left index -->
                    <body name="left_index_1" pos="0.025387 -0.00056467 -0.20686" quat="0.491197 -0.508648 -0.50865 0.491199">
                      <inertial pos="-0.00183599 0.0123544 -0.00665153" quat="0.4848 0.514683 -0.484931 0.514696" mass="0.0071995" diaginertia="1.32915e-06 1.28615e-06 5.76927e-07"/>
                      <joint name="left_index_1_joint" class="hand" pos="0 0 0" axis="0 0 1" range="0 1.6"/>
                      <geom type="mesh" rgba="0.9 0.9 0.9 1" mesh="left_index_1"/>

                      <body name="left_index_2" pos="-0.0016312 0.032734 -0.00055">
                        <inertial pos="0.00040542 0.0257004 -0.00610831" quat="0.702978 0.703607 0.0750632 0.0715825" mass="0.00968688" diaginertia="2.34233e-06 2.30248e-06 3.04577e-07"/>
                        <joint name="left_index_2_joint" class="hand" pos="0 0 0" axis="0 0 1" range="0 3.14"/>
                        <geom type="mesh" rgba="0.9 0.9 0.9 1" mesh="left_index_2"/>
                      </body>
                    </body>

                    <!-- Left middle -->
                    <body name="left_middle_1" pos="0.0037996 -0.00056467 -0.207" quat="0.499998 -0.5 -0.500002 0.5">
                      <inertial pos="-0.00229271 0.0122779 -0.00665151" quat="0.475172 0.523583 -0.475307 0.523598" mass="0.0071995" diaginertia="1.32913e-06 1.28614e-06 5.76927e-07"/>
                      <joint name="left_middle_1_joint" class="hand" pos="0 0 0" axis="0 0 1" range="0 1.6"/>
                      <geom type="mesh" rgba="0.9 0.9 0.9 1" mesh="left_middle_1"/>

                      <body name="left_middle_2" pos="-0.0028436 0.032651 -0.00055">
                        <inertial pos="7.51984e-05 0.0274488 -0.00610023" quat="0.703913 0.703925 0.067032 0.0670976" mass="0.0104612" diaginertia="2.84801e-06 2.80723e-06 3.32779e-07"/>
                        <joint name="left_middle_2_joint" class="hand" pos="0 0 0" axis="0 0 1" range="0 3.14"/>
                        <geom type="mesh" rgba="0.9 0.9 0.9 1" mesh="left_middle_2"/>
                      </body>
                    </body>

                    <!-- Left ring -->
                    <body name="left_ring_1" pos="-0.017813 -0.00056467 -0.20614" quat="0.512925 -0.48673 -0.486732 0.512927">
                      <inertial pos="-0.0024053 0.0122563 -0.00665151" quat="0.472763 0.525759 -0.4729 0.525774" mass="0.0071995" diaginertia="1.32913e-06 1.28613e-06 5.76927e-07"/>
                      <joint name="left_ring_1_joint" class="hand" pos="0 0 0" axis="0 0 1" range="0 1.6"/>
                      <geom type="mesh" rgba="0.9 0.9 0.9 1" mesh="left_ring_1"/>

                      <body name="left_ring_2" pos="-0.0031431 0.032624 -0.00055">
                        <inertial pos="0.000667145 0.0256949 -0.0061083" quat="0.703335 0.703979 0.0714872 0.0679937" mass="0.00968685" diaginertia="2.34233e-06 2.30247e-06 3.04576e-07"/>
                        <joint name="left_ring_2_joint" class="hand" pos="0 0 0" axis="0 0 1" range="0 3.14"/>
                        <geom type="mesh" rgba="0.9 0.9 0.9 1" mesh="left_ring_2"/>
                      </body>
                    </body>

                    <!-- Left little -->
                    <body name="left_little_1" pos="-0.039144 -0.00056467 -0.20226" quat="0.525476 -0.473152 -0.473154 0.525478">
                      <inertial pos="-0.00316889 0.0120815 -0.00665149" quat="0.456037 0.540325 -0.456186 0.540346" mass="0.00719946" diaginertia="1.32912e-06 1.28612e-06 5.76925e-07"/>
                      <joint name="left_little_1_joint" class="hand" pos="0 0 0" axis="0 0 1" range="0 1.6"/>
                      <geom type="mesh" rgba="0.9 0.9 0.9 1" mesh="left_little_1"/>

                      <body name="left_little_2" pos="-0.005182 0.032363 -0.00055">
                        <inertial pos="0.00469504 0.020442 -0.00610049" quat="0.706681 0.706688 0.0244341 0.0244339" mass="0.00759268" diaginertia="1.28165e-06 1.23907e-06 2.26503e-07"/>
                        <joint name="left_little_2_joint" class="hand" pos="0 0 0" axis="0 0 1" range="0 3.14"/>
                        <geom type="mesh" rgba="0.9 0.9 0.9 1" mesh="left_little_2"/>
                      </body>
                    </body>

                  </body>
                </body>
              </body>
            </body>
          </body>
        </body>
      </body>
    </body>
  </worldbody>

  <!-- Exclude contact information -->
  <contact>
    <exclude body1="world" body2="base_link"/>
    <exclude body1="world" body2="neck_link1"/>
    <exclude body1="world" body2="neck_link2"/>
    <exclude body1="world" body2="arm_r_link4"/>
    <exclude body1="world" body2="arm_r_link5"/>
    <exclude body1="world" body2="arm_r_link6"/>
    <exclude body1="world" body2="arm_r_link7"/>
    <exclude body1="world" body2="right_thumb_1"/>
    <exclude body1="world" body2="right_thumb_2"/>
    <exclude body1="world" body2="right_thumb_3"/>
    <exclude body1="world" body2="right_thumb_4"/>
    <exclude body1="world" body2="right_index_1"/>
    <exclude body1="world" body2="right_index_2"/>
    <exclude body1="world" body2="right_middle_1"/>
    <exclude body1="world" body2="right_middle_2"/>
    <exclude body1="world" body2="right_ring_1"/>
    <exclude body1="world" body2="right_ring_2"/>
    <exclude body1="world" body2="right_little_1"/>
    <exclude body1="world" body2="right_little_2"/>
    <exclude body1="world" body2="arm_l_link4"/>
    <exclude body1="world" body2="arm_l_link5"/>
    <exclude body1="world" body2="arm_l_link6"/>
    <exclude body1="world" body2="arm_l_link7"/>
    <exclude body1="world" body2="left_thumb_1"/>
    <exclude body1="world" body2="left_thumb_2"/>
    <exclude body1="world" body2="left_thumb_3"/>
    <exclude body1="world" body2="left_thumb_4"/>
    <exclude body1="world" body2="left_index_1"/>
    <exclude body1="world" body2="left_index_2"/>
    <exclude body1="world" body2="left_middle_1"/>
    <exclude body1="world" body2="left_middle_2"/>
    <exclude body1="world" body2="left_ring_1"/>
    <exclude body1="world" body2="left_ring_2"/>
    <exclude body1="world" body2="left_little_1"/>
    <exclude body1="world" body2="left_little_2"/>
    <exclude body1="arm_r_link7" body2="right_thumb_2"/>
    <exclude body1="arm_l_link7" body2="left_thumb_2"/>
  </contact>

  <!-- Actuators (position type for each joint) -->
  <actuator>
    <!--
      Slider: linear_joint
      range = 0 0.25
    -->
    <position name="actuator_linear_joint" joint="linear_joint" class="slider" ctrlrange="0 0.25"/>

    <!--
      Neck joints:
      neck_joint1 -> range=0 0.4
      neck_joint2 -> range=-0.6 0.6
    -->
    <position name="actuator_neck_joint1" joint="neck_joint1" class="robot" ctrlrange="0 0.4"/>
    <position name="actuator_neck_joint2" joint="neck_joint2" class="robot" ctrlrange="-0.6 0.6"/>

    <!--
      Right arm joints:
      arm_r_joint1 -> range=-3.14 3.14
      arm_r_joint2 -> range=0 3.14
      arm_r_joint3 -> range=-1.57 1.57
      arm_r_joint4 -> range=-1.86 1.86
      arm_r_joint5 -> range=-1.57 1.57
      arm_r_joint6 -> range=-1.57 1.57
      arm_r_joint7 -> range=-1.046 1.046
    -->
    <position name="actuator_arm_r_joint1" joint="arm_r_joint1" class="robot" ctrlrange="-3.14 3.14"/>
    <position name="actuator_arm_r_joint2" joint="arm_r_joint2" class="robot" ctrlrange="0 3.14"/>
    <position name="actuator_arm_r_joint3" joint="arm_r_joint3" class="robot" ctrlrange="-1.57 1.57"/>
    <position name="actuator_arm_r_joint4" joint="arm_r_joint4" class="robot" ctrlrange="-1.86 1.86"/>
    <position name="actuator_arm_r_joint5" joint="arm_r_joint5" class="robot" ctrlrange="-1.57 1.57"/>
    <position name="actuator_arm_r_joint6" joint="arm_r_joint6" class="robot" ctrlrange="-1.57 1.57"/>
    <position name="actuator_arm_r_joint7" joint="arm_r_joint7" class="robot" ctrlrange="-1.046 1.046"/>

    <!--
      Left arm joints:
      arm_l_joint1 -> range=-3.14 3.14
      arm_l_joint2 -> range=0 3.14
      arm_l_joint3 -> range=-6.28 6.28
      arm_l_joint4 -> range=-1.86 1.86
      arm_l_joint5 -> range=-1.57 1.57
      arm_l_joint6 -> range=-1.57 1.57
      arm_l_joint7 -> range=-1.046 1.046
    -->
    <position name="actuator_arm_l_joint1" joint="arm_l_joint1" class="robot" ctrlrange="-3.14 3.14"/>
    <position name="actuator_arm_l_joint2" joint="arm_l_joint2" class="robot" ctrlrange="0 3.14"/>
    <position name="actuator_arm_l_joint3" joint="arm_l_joint3" class="robot" ctrlrange="-6.28 6.28"/>
    <position name="actuator_arm_l_joint4" joint="arm_l_joint4" class="robot" ctrlrange="-1.86 1.86"/>
    <position name="actuator_arm_l_joint5" joint="arm_l_joint5" class="robot" ctrlrange="-1.57 1.57"/>
    <position name="actuator_arm_l_joint6" joint="arm_l_joint6" class="robot" ctrlrange="-1.57 1.57"/>
    <position name="actuator_arm_l_joint7" joint="arm_l_joint7" class="robot" ctrlrange="-1.046 1.046"/>

    <!-- Right hand actuators -->
    <!-- right_thumb_1_joint: range=0 1.15 -->
    <position name="actuator_right_thumb_1" joint="right_thumb_1_joint" class="hand" ctrlrange="0 1.15"/>
    <!-- right_thumb_2_joint: range=0 0.55 -->
    <position name="actuator_right_thumb_2" joint="right_thumb_2_joint" class="hand" ctrlrange="0 0.55"/>
    <!-- right_thumb_3_joint: range=0 3.14 -->
    <position name="actuator_right_thumb_3" joint="right_thumb_3_joint" class="hand" ctrlrange="0 3.14"/>
    <!-- right_thumb_4_joint: range=0 3.14 -->
    <position name="actuator_right_thumb_4" joint="right_thumb_4_joint" class="hand" ctrlrange="0 3.14"/>

    <!-- right_index_1_joint: range=0 1.6 -->
    <position name="actuator_right_index_1" joint="right_index_1_joint" class="hand" ctrlrange="0 1.6"/>
    <!-- right_index_2_joint: range=0 3.14 -->
    <position name="actuator_right_index_2" joint="right_index_2_joint" class="hand" ctrlrange="0 3.14"/>

    <!-- right_middle_1_joint: range=0 1.6 -->
    <position name="actuator_right_middle_1" joint="right_middle_1_joint" class="hand" ctrlrange="0 1.6"/>
    <!-- right_middle_2_joint: range=0 3.14 -->
    <position name="actuator_right_middle_2" joint="right_middle_2_joint" class="hand" ctrlrange="0 3.14"/>

    <!-- right_ring_1_joint: range=0 1.6 -->
    <position name="actuator_right_ring_1" joint="right_ring_1_joint" class="hand" ctrlrange="0 1.6"/>
    <!-- right_ring_2_joint: range=0 3.14 -->
    <position name="actuator_right_ring_2" joint="right_ring_2_joint" class="hand" ctrlrange="0 3.14"/>

    <!-- right_little_1_joint: range=0 1.6 -->
    <position name="actuator_right_little_1" joint="right_little_1_joint" class="hand" ctrlrange="0 1.6"/>
    <!-- right_little_2_joint: range=0 3.14 -->
    <position name="actuator_right_little_2" joint="right_little_2_joint" class="hand" ctrlrange="0 3.14"/>

    <!-- Left hand actuators -->
    <!-- left_thumb_1_joint: range=0 1.15 -->
    <position name="actuator_left_thumb_1" joint="left_thumb_1_joint" class="hand" ctrlrange="0 1.15"/>
    <!-- left_thumb_2_joint: range=0 0.55 -->
    <position name="actuator_left_thumb_2" joint="left_thumb_2_joint" class="hand" ctrlrange="0 0.55"/>
    <!-- left_thumb_3_joint: range=0 3.14 -->
    <position name="actuator_left_thumb_3" joint="left_thumb_3_joint" class="hand" ctrlrange="0 3.14"/>
    <!-- left_thumb_4_joint: range=0 3.14 -->
    <position name="actuator_left_thumb_4" joint="left_thumb_4_joint" class="hand" ctrlrange="0 3.14"/>

    <!-- left_index_1_joint: range=0 1.6 -->
    <position name="actuator_left_index_1" joint="left_index_1_joint" class="hand" ctrlrange="0 1.6"/>
    <!-- left_index_2_joint: range=0 3.14 -->
    <position name="actuator_left_index_2" joint="left_index_2_joint" class="hand" ctrlrange="0 3.14"/>

    <!-- left_middle_1_joint: range=0 1.6 -->
    <position name="actuator_left_middle_1" joint="left_middle_1_joint" class="hand" ctrlrange="0 1.6"/>
    <!-- left_middle_2_joint: range=0 3.14 -->
    <position name="actuator_left_middle_2" joint="left_middle_2_joint" class="hand" ctrlrange="0 3.14"/>

    <!-- left_ring_1_joint: range=0 1.6 -->
    <position name="actuator_left_ring_1" joint="left_ring_1_joint" class="hand" ctrlrange="0 1.6"/>
    <!-- left_ring_2_joint: range=0 3.14 -->
    <position name="actuator_left_ring_2" joint="left_ring_2_joint" class="hand" ctrlrange="0 3.14"/>

    <!-- left_little_1_joint: range=0 1.6 -->
    <position name="actuator_left_little_1" joint="left_little_1_joint" class="hand" ctrlrange="0 1.6"/>
    <!-- left_little_2_joint: range=0 3.14 -->
    <position name="actuator_left_little_2" joint="left_little_2_joint" class="hand" ctrlrange="0 3.14"/>
  </actuator>
</mujoco>
